File: examples/nep_potentials/Carbon/D_Uniaxial_Tension/Uniaxial_Tension_Results.txt
#The following results were obtained by uniaxial tension of diamond under strain rate of 1e-9 with NEP3 potential.
#Strain     Stress(GPa)
0.000000    0.012281
0.000221    0.295921
0.000441    0.523077
0.000662    0.707840
0.000883    1.030979
0.001104    1.232795
0.001324    1.458144
0.001545    1.717655
0.001766    1.944919
0.001986    2.196360
0.002207    2.340263
0.002428    2.624396
0.002648    2.949223
0.002869    3.175325
0.003090    3.410806
0.003311    3.603937
0.003531    3.830062
0.003752    4.174321
0.003973    4.246298
0.004193    4.570913
0.004414    4.704132
0.004635    4.929977
0.004856    5.171613
0.005076    5.487964
0.005297    5.710780
0.005518    5.952513
0.005738    6.185155
0.005959    6.393844
0.006180    6.585558
0.006401    6.889806
0.006621    7.018627
0.006842    7.334631
0.007063    7.645076
0.007283    7.804756
0.007504    8.007729
0.007725    8.299404
0.007945    8.536338
0.008166    8.783493
0.008387    9.081342
0.008608    9.299894
0.008828    9.389998
0.009049    9.659527
0.009270    9.956155
0.009490    10.246618
0.009711    10.359003
0.009932    10.532981
0.010153    10.830086
0.010373    11.171462
0.010594    11.288186
0.010815    11.523564
0.011035    11.790482
0.011256    12.033375
0.011477    12.279118
0.011697    12.499592
0.011918    12.742330
0.012139    12.955493
0.012360    13.186873
0.012580    13.448879
0.012801    13.675166
0.013022    13.790266
0.013242    14.117919
0.013463    14.341129
0.013684    14.556600
0.013905    14.775112
0.014125    15.106627
0.014346    15.336937
0.014567    15.579177
0.014787    15.738721
0.015008    15.988252
0.015229    16.248637
0.015449    16.463198
0.015670    16.754183
0.015891    16.971781
0.016112    17.096925
0.016332    17.380245
0.016553    17.618339
0.016774    17.808618
0.016994    18.165318
0.017215    18.254703
0.017436    18.488495
0.017657    18.758829
0.017877    18.882012
0.018098    19.129036
0.018319    19.418019
0.018539    19.652708
0.018760    19.810007
0.018981    20.084245
0.019202    20.378472
0.019422    20.531557
0.019643    20.785103
0.019864    20.950959
0.020084    21.216998
0.020305    21.486090
0.020526    21.740972
0.020746    22.039866
0.020967    22.218354
0.021188    22.339745
0.021409    22.520018
0.021629    22.791485
0.021850    23.071750
0.022071    23.253174
0.022291    23.514610
0.022512    23.748681
0.022733    23.978934
0.022954    24.227453
0.023174    24.329048
0.023395    24.643082
0.023616    24.890804
0.023836    25.149640
0.024057    25.364469
0.024278    25.510540
0.024498    25.773429
0.024719    25.937500
0.024940    26.159866
0.025161    26.428659
0.025381    26.629100
0.025602    26.863031
0.025823    27.092817
0.026043    27.270887
0.026264    27.580209
0.026485    27.731371
0.026706    28.002115
0.026926    28.281519
0.027147    28.511977
0.027368    28.715362
0.027588    28.952216
0.027809    29.106917
0.028030    29.248688
0.028250    29.551091
0.028471    29.743759
0.028692    30.036240
0.028913    30.198198
0.029133    30.446261
0.029354    30.685603
0.029575    30.925889
0.029795    31.136112
0.030016    31.338140
0.030237    31.533487
0.030458    31.755617
0.030678    31.980452
0.030899    32.280876
0.031120    32.426290
0.031340    32.632007
0.031561    33.003210
0.031782    33.085498
0.032003    33.370021
0.032223    33.529014
0.032444    33.798844
0.032665    33.901926
0.032885    34.182222
0.033106    34.386940
0.033327    34.700321
0.033547    34.805210
0.033768    35.042710
0.033989    35.287051
0.034210    35.500738
0.034430    35.742805
0.034651    35.925171
0.034872    36.163367
0.035092    36.384510
0.035313    36.614535
0.035534    36.828925
0.035755    37.031506
0.035975    37.235278
0.036196    37.475353
0.036417    37.680740
0.036637    37.890658
0.036858    38.132617
0.037079    38.316870
0.037299    38.540746
0.037520    38.748289
0.037741    38.956633
0.037962    39.192334
0.038182    39.427667
0.038403    39.649604
0.038624    39.831369
0.038844    40.047428
0.039065    40.252078
0.039286    40.519764
0.039507    40.676209
0.039727    40.950209
0.039948    41.133201
0.040169    41.339785
0.040389    41.554539
0.040610    41.695944
0.040831    41.923662
0.041052    42.169477
0.041272    42.414716
0.041493    42.623662
0.041714    42.806530
0.041934    42.921082
0.042155    43.219912
0.042376    43.428841
0.042596    43.565052
0.042817    43.833832
0.043038    43.983926
0.043259    44.228325
0.043479    44.472469
0.043700    44.678731
0.043921    44.887047
0.044141    45.080382
0.044362    45.298452
0.044583    45.547779
0.044804    45.695082
0.045024    45.902132
0.045245    46.098357
0.045466    46.304005
0.045686    46.537873
0.045907    46.742391
0.046128    46.953248
0.046348    47.176921
0.046569    47.337599
0.046790    47.572310
0.047011    47.753200
0.047231    47.950563
0.047452    48.232332
0.047673    48.423055
0.047893    48.598755
0.048114    48.784795
0.048335    49.036814
0.048556    49.237749
0.048776    49.422925
0.048997    49.622921
0.049218    49.800465
0.049438    50.010372
0.049659    50.216069
0.049880    50.429675
0.050100    50.645684
0.050321    50.780681
0.050542    50.998315
0.050763    51.214295
0.050983    51.413970
0.051204    51.639208
0.051425    51.813858
0.051645    51.999798
0.051866    52.186666
0.052087    52.392193
0.052308    52.631891
0.052528    52.810718
0.052749    53.006182
0.052970    53.164714
0.053190    53.382188
0.053411    53.573301
0.053632    53.845031
0.053853    54.025416
0.054073    54.246521
0.054294    54.437483
0.054515    54.621542
0.054735    54.824282
0.054956    54.991030
0.055177    55.189786
0.055397    55.382555
0.055618    55.573998
0.055839    55.794733
0.056060    55.987139
0.056280    56.149930
0.056501    56.380041
0.056722    56.545250
0.056942    56.719268
0.057163    56.968296
0.057384    57.154755
0.057605    57.319307
0.057825    57.546583
0.058046    57.750410
0.058267    57.882632
0.058487    58.113386
0.058708    58.304874
0.058929    58.477697
0.059149    58.706044
0.059370    58.882750
0.059591    59.047912
0.059812    59.262608
0.060032    59.444479
0.060253    59.649859
0.060474    59.854378
0.060694    60.013572
0.060915    60.204494
0.061136    60.423697
0.061357    60.578151
0.061577    60.774709
0.061798    60.949007
0.062019    61.157006
0.062239    61.369084
0.062460    61.532978
0.062681    61.718917
0.062901    61.917781
0.063122    62.155496
0.063343    62.270712
0.063564    62.499710
0.063784    62.671621
0.064005    62.879404
0.064226    63.037169
0.064446    63.209455
0.064667    63.414632
0.064888    63.616129
0.065109    63.802689
0.065329    64.003927
0.065550    64.199124
0.065771    64.337166
0.065991    64.525505
0.066212    64.740417
0.066433    64.895761
0.066654    65.086075
0.066874    65.277185
0.067095    65.457420
0.067316    65.667213
0.067536    65.857171
0.067757    66.024983
0.067978    66.192794
0.068198    66.413761
0.068419    66.555238
0.068640    66.754090
0.068861    66.950527
0.069081    67.130482
0.069302    67.297253
0.069523    67.494216
0.069743    67.672368
0.069964    67.833838
0.070185    68.050651
0.070406    68.210269
0.070626    68.382221
0.070847    68.583705
0.071068    68.766415
0.071288    68.930233
0.071509    69.141088
0.071730    69.303260
0.071950    69.486392
0.072171    69.678376
0.072392    69.822607
0.072613    70.040117
0.072833    70.179564
0.073054    70.376805
0.073275    70.566517
0.073495    70.765238
0.073716    70.931409
0.073937    71.097207
0.074158    71.267792
0.074378    71.465851
0.074599    71.649894
0.074820    71.808239
0.075040    71.997095
0.075261    72.135067
0.075482    72.358306
0.075703    72.520418
0.075923    72.676496
0.076144    72.887571
0.076365    73.042947
0.076585    73.246384
0.076806    73.411384
0.077027    73.557366
0.077247    73.749530
0.077468    73.921948
0.077689    74.095217
0.077910    74.296891
0.078130    74.496359
0.078351    74.646903
0.078572    74.789816
0.078792    74.983263
0.079013    75.161706
0.079234    75.367089
0.079455    75.527634
0.079675    75.680563
0.079896    75.848583
0.080117    75.997021
0.080337    76.155900
0.080558    76.375417
0.080779    76.542080
0.080999    76.722720
0.081220    76.889675
0.081441    77.042532
0.081662    77.222019
0.081882    77.447075
0.082103    77.568973
0.082324    77.721221
0.082544    77.878836
0.082765    78.071156
0.082986    78.209479
0.083207    78.369892
0.083427    78.591839
0.083648    78.756097
0.083869    78.907194
0.084089    79.070090
0.084310    79.251747
0.084531    79.461659
0.084751    79.588871
0.084972    79.741658
0.085193    79.916291
0.085414    80.114886
0.085634    80.302556
0.085855    80.478557
0.086076    80.637927
0.086296    80.797466
0.086517    80.926672
0.086738    81.099236
0.086959    81.266753
0.087179    81.444887
0.087400    81.603611
0.087621    81.752889
0.087841    81.936203
0.088062    82.089763
0.088283    82.234438
0.088504    82.451733
0.088724    82.567215
0.088945    82.767470
0.089166    82.912800
0.089386    83.104678
0.089607    83.277078
0.089828    83.452746
0.090048    83.588417
0.090269    83.730606
0.090490    83.906615
0.090711    84.084172
0.090931    84.255571
0.091152    84.429635
0.091373    84.561386
0.091593    84.759150
0.091814    84.885479
0.092035    85.086676
0.092256    85.209018
0.092476    85.393229
0.092697    85.528768
0.092918    85.722390
0.093138    85.896325
0.093359    86.047722
0.093580    86.178072
0.093800    86.324921
0.094021    86.514902
0.094242    86.698907
0.094463    86.845882
0.094683    86.996154
0.094904    87.177653
0.095125    87.320535
0.095345    87.485471
0.095566    87.638471
0.095787    87.760206
0.096008    87.949213
0.096228    88.105551
0.096449    88.249040
0.096670    88.427089
0.096890    88.538193
0.097111    88.740732
0.097332    88.920971
0.097552    89.016267
0.097773    89.175240
0.097994    89.342721
0.098215    89.505933
0.098435    89.721082
0.098656    89.840265
0.098877    90.001417
0.099097    90.138048
0.099318    90.316819
0.099539    90.464183
0.099760    90.571064
0.099980    90.757186
0.100201    90.943106
0.100422    91.077223
0.100642    91.217871
0.100863    91.377759
0.101084    91.534358
0.101305    91.722309
0.101525    91.866225
0.101746    92.014506
0.101967    92.203482
0.102187    92.315324
0.102408    92.453756
0.102629    92.629427
0.102849    92.745326
0.103070    92.926721
0.103291    93.073449
0.103512    93.184128
0.103732    93.391707
0.103953    93.497485
0.104174    93.699111
0.104394    93.840146
0.104615    93.981716
0.104836    94.151613
0.105057    94.347908
0.105277    94.471642
0.105498    94.580154
0.105719    94.773757
0.105939    94.917789
0.106160    95.050661
0.106381    95.142767
0.106601    95.331680
0.106822    95.520764
0.107043    95.683422
0.107264    95.804026
0.107484    95.975362
0.107705    96.104016
0.107926    96.256312
0.108146    96.347144
0.108367    96.530337
0.108588    96.662690
0.108809    96.804663
0.109029    96.957615
0.109250    97.113766
0.109471    97.310475
0.109691    97.466312
0.109912    97.627712
0.110133    97.763680
0.110354    97.877154
0.110574    98.027645
0.110795    98.213173
0.111016    98.342884
0.111236    98.507591
0.111457    98.598576
0.111678    98.777005
0.111898    98.897831
0.112119    99.024109
0.112340    99.212462
0.112561    99.336167
0.112781    99.476686
0.113002    99.558483
0.113223    99.726120
0.113443    99.943755
0.113664    100.078024
0.113885    100.212897
0.114106    100.382832
0.114326    100.507196
0.114547    100.675836
0.114768    100.814056
0.114988    100.963651
0.115209    101.036051
0.115430    101.209187
0.115650    101.340291
0.115871    101.499293
0.116092    101.655460
0.116313    101.767620
0.116533    101.934709
0.116754    102.068787
0.116975    102.221539
0.117195    102.368464
0.117416    102.494664
0.117637    102.675280
0.117858    102.789031
0.118078    102.941348
0.118299    103.066597
0.118520    103.196844
0.118740    103.346665
0.118961    103.494562
0.119182    103.626717
0.119402    103.788532
0.119623    103.932821
0.119844    104.060859
0.120065    104.187416
0.120285    104.356145
0.120506    104.485531
0.120727    104.606009
0.120947    104.751640
0.121168    104.894403
0.121389    105.064352
0.121610    105.192800
0.121830    105.351978
0.122051    105.488169
0.122272    105.612804
0.122492    105.752783
0.122713    105.861086
0.122934    106.029259
0.123155    106.156728
0.123375    106.294220
0.123596    106.420592
0.123817    106.573940
0.124037    106.695796
0.124258    106.899548
0.124479    107.030121
0.124699    107.151978
0.124920    107.255788
0.125141    107.368407
0.125362    107.538422
0.125582    107.644512
0.125803    107.794093
0.126024    107.926876
0.126244    108.067103
0.126465    108.211201
0.126686    108.361374
0.126907    108.459574
0.127127    108.613120
0.127348    108.727024
0.127569    108.922567
0.127789    109.038286
0.128010    109.154491
0.128231    109.300434
0.128451    109.422839
0.128672    109.588036
0.128893    109.703706
0.129114    109.816620
0.129334    109.910559
0.129555    110.080104
0.129776    110.182974
0.129996    110.355729
0.130217    110.474469
0.130438    110.616313
0.130659    110.765365
0.130879    110.931238
0.131100    111.050772
0.131321    111.188558
0.131541    111.306972
0.131762    111.454460
0.131983    111.578042
0.132203    111.727570
0.132424    111.857471
0.132645    111.974426
0.132866    112.123668
0.133086    112.279261
0.133307    112.393412
0.133528    112.484602
0.133748    112.660013
0.133969    112.758642
0.134190    112.883273
0.134411    112.982704
0.134631    113.109491
0.134852    113.278752
0.135073    113.406715
0.135293    113.541321
0.135514    113.657423
0.135735    113.786724
0.135956    113.913761
0.136176    114.038518
0.136397    114.176472
0.136618    114.334177
0.136838    114.451356
0.137059    114.636987
0.137280    114.762641
0.137500    114.897923
0.137721    115.011840
0.137942    115.135745
0.138163    115.225739
0.138383    115.420494
0.138604    115.492620
0.138825    115.635748
0.139045    115.744248
0.139266    115.882937
0.139487    115.988384
0.139708    116.102374
0.139928    116.313247
0.140149    116.413621
0.140370    116.536442
0.140590    116.613590
0.140811    116.798785
0.141032    116.890994
0.141252    117.022410
0.141473    117.146037
0.141694    117.310076
0.141915    117.456478
0.142135    117.528136
0.142356    117.666272
0.142577    117.803164
0.142797    117.930710
0.143018    118.042926
0.143239    118.151827
0.143460    118.300808
0.143680    118.416121
0.143901    118.583987
0.144122    118.715834
0.144342    118.815440
0.144563    118.959791
0.144784    119.114948
0.145005    119.255961
0.145225    119.317520
0.145446    119.446363
0.145667    119.577720
0.145887    119.693184
0.146108    119.827059
0.146329    119.971090
0.146549    120.122114
0.146770    120.253277
0.146991    120.363299
0.147212    120.437897
0.147432    120.589573
0.147653    120.700933
0.147874    120.797444
0.148094    120.956448
0.148315    121.079664
0.148536    121.216891
0.148757    121.364255
0.148977    121.467483
0.149198    121.672195
0.149419    121.779168
0.149639    121.876082
0.149860    122.005093
0.150081    122.147046
0.150301    122.231452
0.150522    122.362830
0.150743    122.492900
0.150964    122.614446
0.151184    122.745986
0.151405    122.870766
0.151626    123.029516
0.151846    123.125406
0.152067    123.240303
0.152288    123.348522
0.152509    123.500031
0.152729    123.590935
0.152950    123.745819
0.153171    123.887046
0.153391    123.994963
0.153612    124.092488
0.153833    124.209055
0.154053    124.350963
0.154274    124.524950
0.154495    124.646825
0.154716    124.745269
0.154936    124.867266
0.155157    125.000269
0.155378    125.125622
0.155598    125.291144
0.155819    125.377783
0.156040    125.469112
0.156261    125.597096
0.156481    125.727556
0.156702    125.836174
0.156923    125.977324
0.157143    126.096984
0.157364    126.227147
0.157585    126.348111
0.157806    126.473875
0.158026    126.624015
0.158247    126.715212
0.158468    126.849585
0.158688    126.957517
0.158909    127.090639
0.159130    127.238513
0.159350    127.321077
0.159571    127.480945
0.159792    127.578308
0.160013    127.734655
0.160233    127.840090
0.160454    127.959833
0.160675    128.099959
0.160895    128.200069
0.161116    128.338822
0.161337    128.469688
0.161558    128.597863
0.161778    128.699849
0.161999    128.823637
0.162220    128.968124
0.162440    129.080521
0.162661    129.211609
0.162882    129.352238
0.163102    129.504042
0.163323    129.587374
0.163544    129.689468
0.163765    129.845658
0.163985    129.964438
0.164206    130.082995
0.164427    130.210643
0.164647    130.342275
0.164868    130.467904
0.165089    130.574218
0.165310    130.694463
0.165530    130.826736
0.165751    130.922332
0.165972    131.077230
0.166192    131.180504
0.166413    131.322606
0.166634    131.431618
0.166854    131.585961
0.167075    131.690561
0.167296    131.826149
0.167517    131.904457
0.167737    132.071576
0.167958    132.208121
0.168179    132.320924
0.168399    132.470302
0.168620    132.573285
0.168841    132.665454
0.169062    132.821256
0.169282    132.928272
0.169503    133.066003
0.169724    133.182055
0.169944    133.331509
0.170165    133.438764
0.170386    133.552144
0.170607    133.702110
0.170827    133.813867
0.171048    133.943656
0.171269    134.094856
0.171489    134.172536
0.171710    134.287536
0.171931    134.424019
0.172151    134.555959
0.172372    134.716435
0.172593    134.830418
0.172814    134.948089
0.173034    135.076549
0.173255    135.186591
0.173476    135.310168
0.173696    135.478881
0.173917    135.575858
0.174138    135.668277
0.174359    135.827578
0.174579    135.978185
0.174800    136.106010
0.175021    136.205707
0.175241    136.302876
0.175462    136.450913
0.175683    136.592922
0.175903    136.740575
0.176124    136.829874
0.176345    136.924760
0.176566    137.077659
0.176786    137.203911
0.177007    137.334857
0.177228    137.435584
0.177448    137.551165
0.177669    137.737222
0.177890    137.876413
0.178111    137.973695
0.178331    138.098628
0.178552    138.239223
0.178773    138.353875
0.178993    138.465008
0.179214    138.626433
0.179435    138.729285
0.179656    138.860391
0.179876    138.972149
0.180097    139.114798
0.180318    139.247706
0.180538    139.361039
0.180759    139.511899
0.180980    139.647988
0.181200    139.773434
0.181421    139.925298
0.181642    140.047089
0.181863    140.200515
0.182083    140.324447
0.182304    140.441308
0.182525    140.544393
0.182745    140.679150
0.182966    140.781075
0.183187    140.962325
0.183408    141.116082
0.183628    141.190643
0.183849    141.337969
0.184070    141.463841
0.184290    141.588411
0.184511    141.717667
0.184732    141.854771
0.184952    141.977873
0.185173    142.120402
0.185394    142.271650
0.185615    142.407965
0.185835    142.528994
0.186056    142.619507
0.186277    142.783352
0.186497    142.885208
0.186718    143.013945
0.186939    143.194784
0.187160    143.297739
0.187380    143.459382
0.187601    143.575179
0.187822    143.701624
0.188042    143.830513
0.188263    143.966933
0.188484    144.098841
0.188704    144.241641
0.188925    144.372677
0.189146    144.506982
0.189367    144.604075
0.189587    144.778185
0.189808    144.900248
0.190029    145.043946
0.190249    145.174354
0.190470    145.292786
0.190691    145.431559
0.190912    145.591627
0.191132    145.729429
0.191353    145.866568
0.191574    145.955110
0.191794    146.098426
0.192015    146.207092
0.192236    146.367356
0.192457    146.491579
0.192677    146.638477
0.192898    146.789224
0.193119    146.919745
0.193339    147.035996
0.193560    147.183726
0.193781    147.327979
0.194001    147.466309
0.194222    147.598529
0.194443    147.739786
0.194664    147.875380
0.194884    148.018463
0.195105    148.138315
0.195326    148.267966
0.195546    148.401395
0.195767    148.565809
0.195988    148.659375
0.196209    148.810461
0.196429    148.937699
0.196650    149.074931
0.196871    149.181536
0.197091    149.334234
0.197312    149.477493
0.197533    149.596415
0.197753    149.771793
0.197974    149.917724
0.198195    150.008789
0.198416    150.186728
0.198636    150.304708
0.198857    150.431975
0.199078    150.599511
0.199298    150.739817
0.199519    150.875866
0.199740    151.002336
0.199961    151.126409
0.200181    151.275298
0.200402    151.399329
0.200623    151.552868
0.200843    151.646694
0.201064    151.824384
0.201285    151.953800
0.201505    152.104921
0.201726    152.230578
0.201947    152.346965
0.202168    152.533406
0.202388    152.638246
0.202609    152.779820
0.202830    152.894937
0.203050    153.073054
0.203271    153.203711
0.203492    153.333808
0.203713    153.469591
0.203933    153.639372
0.204154    153.767524
0.204375    153.920692
0.204595    154.014224
0.204816    154.149532
0.205037    154.298095
0.205258    154.435026
0.205478    154.554814
0.205699    154.716267
0.205920    154.872595
0.206140    155.003571
0.206361    155.166137
0.206582    155.262013
0.206802    155.446531
0.207023    155.592014
0.207244    155.722630
0.207465    155.855888
0.207685    155.943493
0.207906    156.113232
0.208127    156.231090
0.208347    156.393516
0.208568    156.534452
0.208789    156.664914
0.209010    156.793572
0.209230    156.941566
0.209451    157.078454
0.209672    157.218579
0.209892    157.337405
0.210113    157.459732
0.210334    157.602865
0.210554    157.789909
0.210775    157.931687
0.210996    158.045254
0.211217    158.162534
0.211437    158.323691
0.211658    158.453455
0.211879    158.612111
0.212099    158.747317
0.212320    158.883665
0.212541    159.061656
0.212762    159.175888
0.212982    159.316534
0.213203    159.484634
0.213424    159.581377
0.213644    159.722926
0.213865    159.880141
0.214086    160.000931
0.214307    160.133981
0.214527    160.270238
0.214748    160.426843
0.214969    160.562782
0.215189    160.706560
0.215410    160.881470
0.215631    160.959315
0.215851    161.096271
0.216072    161.235118
0.216293    161.397414
0.216514    161.528145
0.216734    161.646630
0.216955    161.774571
0.217176    161.939260
0.217396    161.994952
0.217617    162.195533
0.217838    162.329931
0.218059    162.466177
0.218279    162.599107
0.218500    162.795045
0.218721    162.945194
0.218941    163.054351
0.219162    163.198104
0.219383    163.373198
0.219603    163.431284
0.219824    163.588631
0.220045    163.703526
0.220266    163.855043
0.220486    163.987794
0.220707    164.185962
0.220928    164.305596
0.221148    164.406147
0.221369    164.542232
0.221590    164.673026
0.221811    164.795459
0.222031    164.988807
0.222252    165.110512
0.222473    165.311134
0.222693    165.402999
0.222914    165.563468
0.223135    165.652127
0.223355    165.798482
0.223576    165.934135
0.223797    166.050221
0.224018    166.209598
0.224238    166.354673
0.224459    166.501959
0.224680    166.665573
0.224900    166.824410
0.225121    166.890910
0.225342    167.039220
0.225563    167.198312
0.225783    167.293597
0.226004    167.463763
0.226225    167.575966
0.226445    167.700197
0.226666    167.852882
0.226887    168.016729
0.227108    168.109088
0.227328    168.291478
0.227549    168.366133
0.227770    168.568547
0.227990    168.699293
0.228211    168.822465
0.228432    168.942371
0.228652    169.057763
0.228873    169.196849
0.229094    169.344149
0.229315    169.443397
0.229535    169.588921
0.229756    169.753390
0.229977    169.829027
0.230197    169.999028
0.230418    170.161923
0.230639    170.331386
0.230860    170.411171
0.231080    170.549389
0.231301    170.685245
0.231522    170.795069
0.231742    170.943357
0.231963    171.094164
0.232184    171.196822
0.232404    171.384005
0.232625    171.521613
0.232846    171.658904
0.233067    171.805520
0.233287    171.840476
0.233508    172.040696
0.233729    172.159625
0.233949    172.319514
0.234170    172.442222
0.234391    172.628438
0.234612    172.654755
0.234832    172.781756
0.235053    172.971941
0.235274    173.030870
0.235494    173.237418
0.235715    173.352344
0.235936    173.516919
0.236157    173.655190
0.236377    173.745366
0.236598    173.966030
0.236819    174.020281
0.237039    174.151391
0.237260    174.226490
0.237481    174.371720
0.237701    174.519963
0.237922    174.694086
0.238143    174.845290
0.238364    174.920728
0.238584    175.008563
0.238805    175.175198
0.239026    175.369123
0.239246    175.412809
0.239467    175.560674
0.239688    175.711282
0.239909    175.833642
0.240129    175.983374
0.240350    176.062187
0.240571    176.220439
0.240791    176.346807
0.241012    176.537910
0.241233    176.646650
0.241453    176.765697
0.241674    176.905980
0.241895    177.052814
0.242116    177.158137
0.242336    177.272370
0.242557    177.348898
0.242778    177.560247
0.242998    177.648849
0.243219    177.806026
0.243440    177.987490
0.243661    177.993819
0.243881    178.125899
0.244102    178.254128
0.244323    178.494289
0.244543    178.557412
0.244764    178.731499
0.244985    178.866116
0.245205    178.896638
0.245426    179.023509
0.245647    179.156607
0.245868    179.285700
0.246088    179.416819
0.246309    179.559043
0.246530    179.737452
0.246750    179.866581
0.246971    179.972548
0.247192    180.029033
0.247413    180.120165
0.247633    180.349260
0.247854    180.457693
0.248075    180.540537
0.248295    180.720367
0.248516    180.827272
0.248737    180.903341
0.248958    180.989860
0.249178    181.134812
0.249399    181.341439
0.249620    181.379246
0.249840    181.567849
0.250061    181.701900
0.250282    181.872457
0.250502    181.988835
0.250723    182.072219
0.250944    182.167719
0.251165    182.215393
0.251385    182.427679
0.251606    182.469118
0.251827    182.604800
0.252047    182.878685
0.252268    182.872314
0.252489    183.138002
0.252710    183.133011
0.252930    183.335984
0.253151    183.374562
0.253372    183.528792
0.253592    183.639005
0.253813    183.752935
0.254034    183.833938
0.254254    183.972981
0.254475    184.081750
0.254696    184.162224
0.254917    184.287653
0.255137    184.514244
0.255358    184.578314
0.255579    184.748279
0.255799    184.878642
0.256020    184.972589
0.256241    185.003216
0.256462    185.151932
0.256682    185.304698
0.256903    185.474459
0.257124    185.602653
0.257344    185.690824
0.257565    185.741133
0.257786    185.862642
0.258006    185.968292
0.258227    186.144563
0.258448    186.183246
0.258669    186.241052
0.258889    186.445536
0.259110    186.593904
0.259331    186.657362
0.259551    186.732117
0.259772    186.893941
0.259993    187.095859
0.260214    187.101057
0.260434    187.304039
0.260655    187.404955
0.260876    187.500002
0.261096    187.609637
0.261317    187.643855
0.261538    187.798494
0.261759    187.868231
0.261979    188.054288
0.262200    188.169964
0.262421    188.353649
0.262641    188.344765
0.262862    188.477569
0.263083    188.592002
0.263303    188.628081
0.263524    188.871773
0.263745    189.008267
0.263966    188.917752
0.264186    189.148716
0.264407    189.216805
0.264628    189.404295
0.264848    189.580889
0.265069    189.555648
0.265290    189.737436
0.265511    189.779326
0.265731    189.937210
0.265952    190.007949
0.266173    190.030636
0.266393    190.184017
0.266614    190.372860
0.266835    190.331701
0.267055    190.552330
0.267276    190.636230
0.267497    190.819952
0.267718    190.929704
0.267938    191.066508
0.268159    191.101082
0.268380    191.193528
0.268600    191.312853
0.268821    191.383053
0.269042    191.474523
0.269263    191.585785
0.269483    191.666730
0.269704    191.836416
0.269925    191.868914
0.270145    192.013844
0.270366    192.037310
0.270587    192.341403
0.270808    192.265707
0.271028    192.375516
0.271249    192.511301
0.271470    192.654427
0.271690    192.728374
0.271911    192.779005
0.272132    192.807142
0.272352    192.934913
0.272573    193.219461
0.272794    193.221137
0.273015    193.387007
0.273235    193.366422
0.273456    193.531936
0.273677    193.559349
0.273897    193.767705
0.274118    193.708352
0.274339    193.878219
0.274560    194.004765
0.274780    194.142216
0.275001    194.271138
0.275222    194.308058
0.275442    194.471871
0.275663    194.553144
0.275884    194.531464
0.276104    194.708325
0.276325    194.727967
0.276546    194.936251
0.276767    194.819265
0.276987    194.965999
0.277208    195.165901
0.277429    195.143631
0.277649    195.234591
0.277870    195.580786
0.278091    195.629409
0.278312    195.704683
0.278532    195.726554
0.278753    195.771486
0.278974    195.901126
0.279194    195.975128
0.279415    195.998341
0.279636    196.160089
0.279856    196.261087
0.280077    196.226231
0.280298    196.371519
0.280519    196.458329
0.280739    196.591432
0.280960    196.695850
0.281181    196.791054
0.281401    196.878911
0.281622    196.748658
0.281843    197.011295
0.282064    196.963314
0.282284    197.141071
0.282505    197.185692
0.282726    197.238846
0.282946    197.263765
0.283167    197.609681
0.283388    197.482833
0.283609    197.651158
0.283829    197.614880
0.284050    197.785844
0.284271    197.949595
0.284491    197.846338
0.284712    198.162756
0.284933    198.334101
0.285153    198.184819
0.285374    198.488900
0.285595    198.397037
0.285816    198.529275
0.286036    198.546434
0.286257    198.662744
0.286478    198.692132
0.286698    198.680358
0.286919    198.752629
0.287140    198.993558
0.287361    198.996889
0.287581    199.113158
0.287802    199.069901
0.288023    199.063199
0.288243    -22.437144
0.288464    1.883284
0.288685    2.488308
0.288905    -0.224876
0.289126    -1.653824
0.289347    2.813130
0.289568    -1.769447
0.289788    1.588249
0.290009    -0.387381
0.290230    0.653475
0.290450    1.706094
0.290671    -0.068792
0.290892    1.746179
0.291113    -1.544601
0.291333    1.696578
0.291554    0.005437
0.291775    0.485022
0.291995    0.146006
0.292216    -1.068772
0.292437    1.953632
0.292657    -0.604938
0.292878    1.937219
0.293099    -0.689039
0.293320    0.585231
0.293540    1.201829
0.293761    -0.220315
0.293982    1.501689
0.294202    -2.057449
0.294423    2.329589
0.294644    -0.649444
0.294865    1.345822
0.295085    0.032308
0.295306    -0.440053
0.295527    2.366523
0.295747    -0.855442
0.295968    1.898991
0.296189    -1.529642
0.296410    2.066035
0.296630    0.332823
0.296851    0.393872
0.297072    0.703771
0.297292    -0.176029
0.297513    2.125443
0.297734    -0.911428
0.297954    0.890530
0.298175    0.328004
0.298396    1.123041
0.298617    0.913303
0.298837    -0.168850
0.299058    1.797029
0.299279    0.642367
0.299499    0.499443
0.299720    0.404030
0.299941    0.456306
0.300162    1.698613
0.300382    -0.755374
0.300603    1.732084
0.300824    0.966107
0.301044    1.218822
0.301265    0.703050
0.301486    0.148367
0.301706    2.292983
0.301927    -0.461724
0.302148    1.621964
0.302369    0.803855
0.302589    1.530522
0.302810    1.034384
0.303031    0.249206
0.303251    2.248335
0.303472    0.446620
0.303693    0.655696
0.303914    1.520167
0.304134    1.074862
0.304355    1.443917
0.304576    0.362407
0.304796    1.858099
0.305017    1.085417
0.305238    0.488562
0.305459    2.048288
0.305679    0.777798
0.305900    1.738926
0.306121    0.812268
0.306341    1.766670
0.306562    1.450957
0.306783    0.691495
0.307003    2.068365
0.307224    0.913306
0.307445    1.592533
0.307666    1.778459
0.307886    1.212740
0.308107    2.024582
0.308328    0.607710
0.308548    2.053692
0.308769    1.525595
0.308990    1.259411
0.309211    2.167413
0.309431    1.000078
0.309652    2.074243
0.309873    0.927220
0.310093    1.883912
0.310314    1.632615
0.310535    1.376523
0.310755    2.170310
0.310976    1.630942
0.311197    1.619373
0.311418    2.036059
0.311638    1.256676
0.311859    1.950283
0.312080    1.491087
0.312300    2.304851
0.312521    1.691379
0.312742    1.656825
0.312963    2.230663
0.313183    1.548273
0.313404    1.741013
0.313625    2.263541
0.313845    1.676834
0.314066    2.360353
0.314287    1.615860
0.314507    2.273538
0.314728    1.994785
0.314949    1.659846
0.315170    2.419989
0.315390    1.751352
0.315611    2.320167
0.315832    2.287026
0.316052    2.199286
0.316273    1.920701
0.316494    2.074272
0.316715    2.243331
0.316935    2.207055
0.317156    2.282955
0.317377    2.541684
0.317597    2.190993
0.317818    2.320305
0.318039    2.290541
0.318260    2.387156
0.318480    2.516905
0.318701    2.269681
0.318922    2.687024
0.319142    2.311847
0.319363    2.339920
0.319584    2.454173
0.319804    1.346130
0.320025    1.844691
0.320246    1.100289
0.320467    1.415316
0.320687    2.223137
0.320908    1.035150
0.321129    0.931787
0.321349    2.103270
0.321570    1.198933
0.321791    1.283755
0.322012    1.850969
0.322232    2.124096
0.322453    0.998117
0.322674    1.593402
0.322894    2.016098
0.323115    1.262495
0.323336    1.527874
0.323556    2.315331
0.323777    1.748326
0.323998    1.350908
0.324219    1.987112
0.324439    1.723042
0.324660    1.248560
0.324881    1.902970
0.325101    2.304480
0.325322    1.426398
0.325543    1.979433
0.325764    2.277492
0.325984    1.382740
0.326205    1.868651
0.326426    2.159563
0.326646    2.059534
0.326867    1.747866
0.326877    2.019213